Workbook

Sheet Gantt Chart (daily)
A1: FitForm AI - Project Gantt Chart (daily), IMP Part B
A2: Steve Flinston (24123119) | 6FTC2062 Individual Major Project | Supervisor: Wong Kim Siong | Updated 31 Oct 2026 (after Session 3)
G5: 46279 | H5: 46280 | I5: 46281 | J5: 46282 | K5: 46283 | L5: 46284 | M5: 46285 | N5: 46286 | O5: 46287 | P5: 46288 | Q5: 46289 | R5: 46290 | S5: 46291 | T5: 46292 | U5: 46293 | V5: 46294 | W5: 46295 | X5: 46296 | Y5: 46297 | Z5: 46298 | AA5: 46299 | AB5: 46300 | AC5: 46301 | AD5: 46302 | AE5: 46303 | AF5: 46304 | AG5: 46305 | AH5: 46306 | AI5: 46307 | AJ5: 46308 | AK5: 46309 | AL5: 46310 | AM5: 46311 | AN5: 46312 | AO5: 46313 | AP5: 46314 | AQ5: 46315 | AR5: 46316 | AS5: 46317 | AT5: 46318 | AU5: 46319 | AV5: 46320 | AW5: 46321 | AX5: 46322 | AY5: 46323 | AZ5: 46324 | BA5: 46325 | BB5: 46326 | BC5: 46327 | BD5: 46328 | BE5: 46329 | BF5: 46330 | BG5: 46331 | BH5: 46332 | BI5: 46333 | BJ5: 46334 | BK5: 46335 | BL5: 46336 | BM5: 46337 | BN5: 46338 | BO5: 46339 | BP5: 46340 | BQ5: 46341 | BR5: 46342 | BS5: 46343 | BT5: 46344 | BU5: 46345 | BV5: 46346 | BW5: 46347 | BX5: 46348 | BY5: 46349 | BZ5: 46350 | CA5: 46351 | CB5: 46352 | CC5: 46353 | CD5: 46354 | CE5: 46355 | CF5: 46356 | CG5: 46357 | CH5: 46358
A6: Task Name | B6: Outline week | C6: Start | D6: End | E6: Days | F6: Status | G6: September 2026 | X6: October 2026 | BC6: November 2026 | CG6: Dec
G7: Week 1 | N7: Week 2 | U7: Week 3 | AB7: Week 4 | AI7: Week 5 | AP7: Week 6 | AW7: Week 7 | BD7: Week 8 | BK7: Week 9 | BR7: Week 10 | BY7: Week 11 | CF7: Week 12
G8: 14 | H8: 15 | I8: 16 | J8: 17 | K8: 18 | L8: 19 | M8: 20 | N8: 21 | O8: 22 | P8: 23 | Q8: 24 | R8: 25 | S8: 26 | T8: 27 | U8: 28 | V8: 29 | W8: 30 | X8: 1 | Y8: 2 | Z8: 3 | AA8: 4 | AB8: 5 | AC8: 6 | AD8: 7 | AE8: 8 | AF8: 9 | AG8: 10 | AH8: 11 | AI8: 12 | AJ8: 13 | AK8: 14 | AL8: 15 | AM8: 16 | AN8: 17 | AO8: 18 | AP8: 19 | AQ8: 20 | AR8: 21 | AS8: 22 | AT8: 23 | AU8: 24 | AV8: 25 | AW8: 26 | AX8: 27 | AY8: 28 | AZ8: 29 | BA8: 30 | BB8: 31 | BC8: 1 | BD8: 2 | BE8: 3 | BF8: 4 | BG8: 5 | BH8: 6 | BI8: 7 | BJ8: 8 | BK8: 9 | BL8: 10 | BM8: 11 | BN8: 12 | BO8: 13 | BP8: 14 | BQ8: 15 | BR8: 16 | BS8: 17 | BT8: 18 | BU8: 19 | BV8: 20 | BW8: 21 | BX8: 22 | BY8: 23 | BZ8: 24 | CA8: 25 | CB8: 26 | CC8: 27 | CD8: 28 | CE8: 29 | CF8: 30 | CG8: 1 | CH8: 2
G9: M | H9: T | I9: W | J9: T | K9: F | L9: S | M9: S | N9: M | O9: T | P9: W | Q9: T | R9: F | S9: S | T9: S | U9: M | V9: T | W9: W | X9: T | Y9: F | Z9: S | AA9: S | AB9: M | AC9: T | AD9: W | AE9: T | AF9: F | AG9: S | AH9: S | AI9: M | AJ9: T | AK9: W | AL9: T | AM9: F | AN9: S | AO9: S | AP9: M | AQ9: T | AR9: W | AS9: T | AT9: F | AU9: S | AV9: S | AW9: M | AX9: T | AY9: W | AZ9: T | BA9: F | BB9: S | BC9: S | BD9: M | BE9: T | BF9: W | BG9: T | BH9: F | BI9: S | BJ9: S | BK9: M | BL9: T | BM9: W | BN9: T | BO9: F | BP9: S | BQ9: S | BR9: M | BS9: T | BT9: W | BU9: T | BV9: F | BW9: S | BX9: S | BY9: M | BZ9: T | CA9: W | CB9: T | CC9: F | CD9: S | CE9: S | CF9: M | CG9: T | CH9: W | CL9: Start date | CM9: End date
A10: 1. Set up Python 3.11 virtual environment (Raspberry Pi OS + laptop) | B10: W1 | C10: =DAY(CL10)&" "&INDEX(Lists!$A$1:$A$12,MONTH(CL10)) -> 14 Sep | D10: =DAY(CM10)&" "&INDEX(Lists!$A$1:$A$12,MONTH(CM10)) -> 2 Oct | E10: =CM10-CL10+1 -> 19 | F10: =IF(COUNTIF(F11:F13,"Done")=3,"Done",IF(COUNTIF(F11:F13,"Not started")=3,"Not started","In progress")) -> Done | CJ10: Heading | CL10: =MIN(CL11:CL13) -> 46279 | CM10: =MAX(CM11:CM13) -> 46297
A11: Install Raspberry Pi OS on the microSD card; first boot of the Pi 5 | C11: 14 Sep | D11: 16 Sep | E11: =IF(OR(CL11="",CM11=""),"",CM11-CL11+1) -> 3 | F11: Done | CJ11: Task | CL11: =IFERROR(IF(TRIM(C11)="","",IF(ISNUMBER(C11),C11,DATE(2026,MATCH(LEFT(MID(TRIM(C11),FIND(" ",TRIM(C11))+1,9),3),Lists!$A$1:$A$12,0),VALUE(LEFT(TRIM(C11),FIND(" ",TRIM(C11))-1))))),"") -> 46279 | CM11: =IFERROR(IF(TRIM(D11)="","",IF(ISNUMBER(D11),D11,DATE(2026,MATCH(LEFT(MID(TRIM(D11),FIND(" ",TRIM(D11))+1,9),3),Lists!$A$1:$A$12,0),VALUE(LEFT(TRIM(D11),FIND(" ",TRIM(D11))-1))))),"") -> 46281
A12: Laptop Python environment; fix library version error | C12: 14 Sep | D12: 18 Sep | E12: =IF(OR(CL12="",CM12=""),"",CM12-CL12+1) -> 5 | F12: Done | CJ12: Task | CL12: =IFERROR(IF(TRIM(C12)="","",IF(ISNUMBER(C12),C12,DATE(2026,MATCH(LEFT(MID(TRIM(C12),FIND(" ",TRIM(C12))+1,9),3),Lists!$A$1:$A$12,0),VALUE(LEFT(TRIM(C12),FIND(" ",TRIM(C12))-1))))),"") -> 46279 | CM12: =IFERROR(IF(TRIM(D12)="","",IF(ISNUMBER(D12),D12,DATE(2026,MATCH(LEFT(MID(TRIM(D12),FIND(" ",TRIM(D12))+1,9),3),Lists!$A$1:$A$12,0),VALUE(LEFT(TRIM(D12),FIND(" ",TRIM(D12))-1))))),"") -> 46283
A13: Pi 5 Python 3.12 virtual environment with uv (OS ships Python 3.13) | C13: 28 Sep | D13: 2 Oct | E13: =IF(OR(CL13="",CM13=""),"",CM13-CL13+1) -> 5 | F13: Done | CJ13: Task | CL13: =IFERROR(IF(TRIM(C13)="","",IF(ISNUMBER(C13),C13,DATE(2026,MATCH(LEFT(MID(TRIM(C13),FIND(" ",TRIM(C13))+1,9),3),Lists!$A$1:$A$12,0),VALUE(LEFT(TRIM(C13),FIND(" ",TRIM(C13))-1))))),"") -> 46293 | CM13: =IFERROR(IF(TRIM(D13)="","",IF(ISNUMBER(D13),D13,DATE(2026,MATCH(LEFT(MID(TRIM(D13),FIND(" ",TRIM(D13))+1,9),3),Lists!$A$1:$A$12,0),VALUE(LEFT(TRIM(D13),FIND(" ",TRIM(D13))-1))))),"") -> 46297
A14: 2. Install and configure OpenCV | B14: W2 | C14: =DAY(CL14)&" "&INDEX(Lists!$A$1:$A$12,MONTH(CL14)) -> 16 Sep | D14: =DAY(CM14)&" "&INDEX(Lists!$A$1:$A$12,MONTH(CM14)) -> 2 Oct | E14: =CM14-CL14+1 -> 17 | F14: =IF(COUNTIF(F15:F16,"Done")=2,"Done",IF(COUNTIF(F15:F16,"Not started")=2,"Not started","In progress")) -> Done | CJ14: Heading | CL14: =MIN(CL15:CL16) -> 46281 | CM14: =MAX(CM15:CM16) -> 46297
A15: Install OpenCV 4.11 on the laptop; test the webcam | C15: 16 Sep | D15: 18 Sep | E15: =IF(OR(CL15="",CM15=""),"",CM15-CL15+1) -> 3 | F15: Done | CJ15: Task | CL15: =IFERROR(IF(TRIM(C15)="","",IF(ISNUMBER(C15),C15,DATE(2026,MATCH(LEFT(MID(TRIM(C15),FIND(" ",TRIM(C15))+1,9),3),Lists!$A$1:$A$12,0),VALUE(LEFT(TRIM(C15),FIND(" ",TRIM(C15))-1))))),"") -> 46281 | CM15: =IFERROR(IF(TRIM(D15)="","",IF(ISNUMBER(D15),D15,DATE(2026,MATCH(LEFT(MID(TRIM(D15),FIND(" ",TRIM(D15))+1,9),3),Lists!$A$1:$A$12,0),VALUE(LEFT(TRIM(D15),FIND(" ",TRIM(D15))-1))))),"") -> 46283
A16: Install OpenCV on the Pi 5; remove conflicting builds | C16: 30 Sep | D16: 2 Oct | E16: =IF(OR(CL16="",CM16=""),"",CM16-CL16+1) -> 3 | F16: Done | CJ16: Task | CL16: =IFERROR(IF(TRIM(C16)="","",IF(ISNUMBER(C16),C16,DATE(2026,MATCH(LEFT(MID(TRIM(C16),FIND(" ",TRIM(C16))+1,9),3),Lists!$A$1:$A$12,0),VALUE(LEFT(TRIM(C16),FIND(" ",TRIM(C16))-1))))),"") -> 46295 | CM16: =IFERROR(IF(TRIM(D16)="","",IF(ISNUMBER(D16),D16,DATE(2026,MATCH(LEFT(MID(TRIM(D16),FIND(" ",TRIM(D16))+1,9),3),Lists!$A$1:$A$12,0),VALUE(LEFT(TRIM(D16),FIND(" ",TRIM(D16))-1))))),"") -> 46297
A17: 3. Install and configure MediaPipe; test camera feed and GPIO wiring for LED/buzzer | B17: W3 | C17: =DAY(CL17)&" "&INDEX(Lists!$A$1:$A$12,MONTH(CL17)) -> 17 Sep | D17: =DAY(CM17)&" "&INDEX(Lists!$A$1:$A$12,MONTH(CM17)) -> 4 Nov | E17: =CM17-CL17+1 -> 49 | F17: =IF(COUNTIF(F18:F21,"Done")=4,"Done",IF(COUNTIF(F18:F21,"Not started")=4,"Not started","In progress")) -> In progress | CJ17: Heading | CL17: =MIN(CL18:CL21) -> 46282 | CM17: =MAX(CM18:CM21) -> 46330
A18: Install MediaPipe on the laptop; test pose on the webcam | C18: 17 Sep | D18: 19 Sep | E18: =IF(OR(CL18="",CM18=""),"",CM18-CL18+1) -> 3 | F18: Done | CJ18: Task | CL18: =IFERROR(IF(TRIM(C18)="","",IF(ISNUMBER(C18),C18,DATE(2026,MATCH(LEFT(MID(TRIM(C18),FIND(" ",TRIM(C18))+1,9),3),Lists!$A$1:$A$12,0),VALUE(LEFT(TRIM(C18),FIND(" ",TRIM(C18))-1))))),"") -> 46282 | CM18: =IFERROR(IF(TRIM(D18)="","",IF(ISNUMBER(D18),D18,DATE(2026,MATCH(LEFT(MID(TRIM(D18),FIND(" ",TRIM(D18))+1,9),3),Lists!$A$1:$A$12,0),VALUE(LEFT(TRIM(D18),FIND(" ",TRIM(D18))-1))))),"") -> 46284
A19: Install MediaPipe 0.10.18 on the Pi 5; run the logic tests | C19: 1 Oct | D19: 3 Oct | E19: =IF(OR(CL19="",CM19=""),"",CM19-CL19+1) -> 3 | F19: Done | CJ19: Task | CL19: =IFERROR(IF(TRIM(C19)="","",IF(ISNUMBER(C19),C19,DATE(2026,MATCH(LEFT(MID(TRIM(C19),FIND(" ",TRIM(C19))+1,9),3),Lists!$A$1:$A$12,0),VALUE(LEFT(TRIM(C19),FIND(" ",TRIM(C19))-1))))),"") -> 46296 | CM19: =IFERROR(IF(TRIM(D19)="","",IF(ISNUMBER(D19),D19,DATE(2026,MATCH(LEFT(MID(TRIM(D19),FIND(" ",TRIM(D19))+1,9),3),Lists!$A$1:$A$12,0),VALUE(LEFT(TRIM(D19),FIND(" ",TRIM(D19))-1))))),"") -> 46298
A20: Pi camera support (rpicam) and AI Camera firmware | C20: 3 Oct | D20: 7 Oct | E20: =IF(OR(CL20="",CM20=""),"",CM20-CL20+1) -> 5 | F20: Done | CJ20: Task | CL20: =IFERROR(IF(TRIM(C20)="","",IF(ISNUMBER(C20),C20,DATE(2026,MATCH(LEFT(MID(TRIM(C20),FIND(" ",TRIM(C20))+1,9),3),Lists!$A$1:$A$12,0),VALUE(LEFT(TRIM(C20),FIND(" ",TRIM(C20))-1))))),"") -> 46298 | CM20: =IFERROR(IF(TRIM(D20)="","",IF(ISNUMBER(D20),D20,DATE(2026,MATCH(LEFT(MID(TRIM(D20),FIND(" ",TRIM(D20))+1,9),3),Lists!$A$1:$A$12,0),VALUE(LEFT(TRIM(D20),FIND(" ",TRIM(D20))-1))))),"") -> 46302
A21: GPIO wiring test of the LEDs and buzzer on the breadboard (moved) | C21: 2 Nov | D21: 4 Nov | E21: =IF(OR(CL21="",CM21=""),"",CM21-CL21+1) -> 3 | F21: Not started | CJ21: Task | CL21: =IFERROR(IF(TRIM(C21)="","",IF(ISNUMBER(C21),C21,DATE(2026,MATCH(LEFT(MID(TRIM(C21),FIND(" ",TRIM(C21))+1,9),3),Lists!$A$1:$A$12,0),VALUE(LEFT(TRIM(C21),FIND(" ",TRIM(C21))-1))))),"") -> 46328 | CM21: =IFERROR(IF(TRIM(D21)="","",IF(ISNUMBER(D21),D21,DATE(2026,MATCH(LEFT(MID(TRIM(D21),FIND(" ",TRIM(D21))+1,9),3),Lists!$A$1:$A$12,0),VALUE(LEFT(TRIM(D21),FIND(" ",TRIM(D21))-1))))),"") -> 46330
A22: 4. Develop MediaPipe Pose landmark extraction (shoulder, elbow, wrist, hip coordinates) | B22: W4 | C22: =DAY(CL22)&" "&INDEX(Lists!$A$1:$A$12,MONTH(CL22)) -> 19 Sep | D22: =DAY(CM22)&" "&INDEX(Lists!$A$1:$A$12,MONTH(CM22)) -> 7 Oct | E22: =CM22-CL22+1 -> 19 | F22: =IF(COUNTIF(F23:F24,"Done")=2,"Done",IF(COUNTIF(F23:F24,"Not started")=2,"Not started","In progress")) -> Done | CJ22: Heading | CL22: =MIN(CL23:CL24) -> 46284 | CM22: =MAX(CM23:CM24) -> 46302
A23: Restructure the prototype into modules (pose_engine.py) | C23: 19 Sep | D23: 25 Sep | E23: =IF(OR(CL23="",CM23=""),"",CM23-CL23+1) -> 7 | F23: Done | CJ23: Task | CL23: =IFERROR(IF(TRIM(C23)="","",IF(ISNUMBER(C23),C23,DATE(2026,MATCH(LEFT(MID(TRIM(C23),FIND(" ",TRIM(C23))+1,9),3),Lists!$A$1:$A$12,0),VALUE(LEFT(TRIM(C23),FIND(" ",TRIM(C23))-1))))),"") -> 46284 | CM23: =IFERROR(IF(TRIM(D23)="","",IF(ISNUMBER(D23),D23,DATE(2026,MATCH(LEFT(MID(TRIM(D23),FIND(" ",TRIM(D23))+1,9),3),Lists!$A$1:$A$12,0),VALUE(LEFT(TRIM(D23),FIND(" ",TRIM(D23))-1))))),"") -> 46290
A24: Use MediaPipe 3D world landmarks (view-independent) | C24: 5 Oct | D24: 7 Oct | E24: =IF(OR(CL24="",CM24=""),"",CM24-CL24+1) -> 3 | F24: Done | CJ24: Task | CL24: =IFERROR(IF(TRIM(C24)="","",IF(ISNUMBER(C24),C24,DATE(2026,MATCH(LEFT(MID(TRIM(C24),FIND(" ",TRIM(C24))+1,9),3),Lists!$A$1:$A$12,0),VALUE(LEFT(TRIM(C24),FIND(" ",TRIM(C24))-1))))),"") -> 46300 | CM24: =IFERROR(IF(TRIM(D24)="","",IF(ISNUMBER(D24),D24,DATE(2026,MATCH(LEFT(MID(TRIM(D24),FIND(" ",TRIM(D24))+1,9),3),Lists!$A$1:$A$12,0),VALUE(LEFT(TRIM(D24),FIND(" ",TRIM(D24))-1))))),"") -> 46302
A25: 5. Implement joint-angle calculation functions (elbow, torso, wrist angles) | B25: W5 | C25: =DAY(CL25)&" "&INDEX(Lists!$A$1:$A$12,MONTH(CL25)) -> 5 Oct | D25: =DAY(CM25)&" "&INDEX(Lists!$A$1:$A$12,MONTH(CM25)) -> 8 Oct | E25: =CM25-CL25+1 -> 4 | F25: =IF(COUNTIF(F26:F27,"Done")=2,"Done",IF(COUNTIF(F26:F27,"Not started")=2,"Not started","In progress")) -> Done | CJ25: Heading | CL25: =MIN(CL26:CL27) -> 46300 | CM25: =MAX(CM26:CM27) -> 46303
A26: Elbow angle and upper-arm drift check (replaces hip swing check) | C26: 5 Oct | D26: 7 Oct | E26: =IF(OR(CL26="",CM26=""),"",CM26-CL26+1) -> 3 | F26: Done | CJ26: Task | CL26: =IFERROR(IF(TRIM(C26)="","",IF(ISNUMBER(C26),C26,DATE(2026,MATCH(LEFT(MID(TRIM(C26),FIND(" ",TRIM(C26))+1,9),3),Lists!$A$1:$A$12,0),VALUE(LEFT(TRIM(C26),FIND(" ",TRIM(C26))-1))))),"") -> 46300 | CM26: =IFERROR(IF(TRIM(D26)="","",IF(ISNUMBER(D26),D26,DATE(2026,MATCH(LEFT(MID(TRIM(D26),FIND(" ",TRIM(D26))+1,9),3),Lists!$A$1:$A$12,0),VALUE(LEFT(TRIM(D26),FIND(" ",TRIM(D26))-1))))),"") -> 46302
A27: Wrist angle from the hand knuckles (MediaPipe Hands) | C27: 7 Oct | D27: 8 Oct | E27: =IF(OR(CL27="",CM27=""),"",CM27-CL27+1) -> 2 | F27: Done | CJ27: Task | CL27: =IFERROR(IF(TRIM(C27)="","",IF(ISNUMBER(C27),C27,DATE(2026,MATCH(LEFT(MID(TRIM(C27),FIND(" ",TRIM(C27))+1,9),3),Lists!$A$1:$A$12,0),VALUE(LEFT(TRIM(C27),FIND(" ",TRIM(C27))-1))))),"") -> 46302 | CM27: =IFERROR(IF(TRIM(D27)="","",IF(ISNUMBER(D27),D27,DATE(2026,MATCH(LEFT(MID(TRIM(D27),FIND(" ",TRIM(D27))+1,9),3),Lists!$A$1:$A$12,0),VALUE(LEFT(TRIM(D27),FIND(" ",TRIM(D27))-1))))),"") -> 46303
A28: 6. Build the bicep curl rep-counting state machine with form-validation checks | B28: W6 | C28: =DAY(CL28)&" "&INDEX(Lists!$A$1:$A$12,MONTH(CL28)) -> 21 Sep | D28: =DAY(CM28)&" "&INDEX(Lists!$A$1:$A$12,MONTH(CM28)) -> 27 Oct | E28: =CM28-CL28+1 -> 37 | F28: =IF(COUNTIF(F29:F34,"Done")=6,"Done",IF(COUNTIF(F29:F34,"Not started")=6,"Not started","In progress")) -> Done | CJ28: Heading | CL28: =MIN(CL29:CL34) -> 46286 | CM28: =MAX(CM29:CM34) -> 46322
A29: State machine for left and right arms (laptop test) | C29: 21 Sep | D29: 26 Sep | E29: =IF(OR(CL29="",CM29=""),"",CM29-CL29+1) -> 6 | F29: Done | CJ29: Task | CL29: =IFERROR(IF(TRIM(C29)="","",IF(ISNUMBER(C29),C29,DATE(2026,MATCH(LEFT(MID(TRIM(C29),FIND(" ",TRIM(C29))+1,9),3),Lists!$A$1:$A$12,0),VALUE(LEFT(TRIM(C29),FIND(" ",TRIM(C29))-1))))),"") -> 46286 | CM29: =IFERROR(IF(TRIM(D29)="","",IF(ISNUMBER(D29),D29,DATE(2026,MATCH(LEFT(MID(TRIM(D29),FIND(" ",TRIM(D29))+1,9),3),Lists!$A$1:$A$12,0),VALUE(LEFT(TRIM(D29),FIND(" ",TRIM(D29))-1))))),"") -> 46291
A30: Clenched-fist check with MediaPipe Hands | C30: 6 Oct | D30: 8 Oct | E30: =IF(OR(CL30="",CM30=""),"",CM30-CL30+1) -> 3 | F30: Done | CJ30: Task | CL30: =IFERROR(IF(TRIM(C30)="","",IF(ISNUMBER(C30),C30,DATE(2026,MATCH(LEFT(MID(TRIM(C30),FIND(" ",TRIM(C30))+1,9),3),Lists!$A$1:$A$12,0),VALUE(LEFT(TRIM(C30),FIND(" ",TRIM(C30))-1))))),"") -> 46301 | CM30: =IFERROR(IF(TRIM(D30)="","",IF(ISNUMBER(D30),D30,DATE(2026,MATCH(LEFT(MID(TRIM(D30),FIND(" ",TRIM(D30))+1,9),3),Lists!$A$1:$A$12,0),VALUE(LEFT(TRIM(D30),FIND(" ",TRIM(D30))-1))))),"") -> 46303
A31: Fix live rep counting on the Pi using the debug view | C31: 8 Oct | D31: 22 Oct | E31: =IF(OR(CL31="",CM31=""),"",CM31-CL31+1) -> 15 | F31: Done | CJ31: Task | CL31: =IFERROR(IF(TRIM(C31)="","",IF(ISNUMBER(C31),C31,DATE(2026,MATCH(LEFT(MID(TRIM(C31),FIND(" ",TRIM(C31))+1,9),3),Lists!$A$1:$A$12,0),VALUE(LEFT(TRIM(C31),FIND(" ",TRIM(C31))-1))))),"") -> 46303 | CM31: =IFERROR(IF(TRIM(D31)="","",IF(ISNUMBER(D31),D31,DATE(2026,MATCH(LEFT(MID(TRIM(D31),FIND(" ",TRIM(D31))+1,9),3),Lists!$A$1:$A$12,0),VALUE(LEFT(TRIM(D31),FIND(" ",TRIM(D31))-1))))),"") -> 46317
A32: Fist direction: per-arm calibration from labelled runs; tip instead of reject | C32: 15 Oct | D32: 21 Oct | E32: =IF(OR(CL32="",CM32=""),"",CM32-CL32+1) -> 7 | F32: Done | CJ32: Task | CL32: =IFERROR(IF(TRIM(C32)="","",IF(ISNUMBER(C32),C32,DATE(2026,MATCH(LEFT(MID(TRIM(C32),FIND(" ",TRIM(C32))+1,9),3),Lists!$A$1:$A$12,0),VALUE(LEFT(TRIM(C32),FIND(" ",TRIM(C32))-1))))),"") -> 46310 | CM32: =IFERROR(IF(TRIM(D32)="","",IF(ISNUMBER(D32),D32,DATE(2026,MATCH(LEFT(MID(TRIM(D32),FIND(" ",TRIM(D32))+1,9),3),Lists!$A$1:$A$12,0),VALUE(LEFT(TRIM(D32),FIND(" ",TRIM(D32))-1))))),"") -> 46316
A33: Pause after a rejected rep with fix text; walk-away ends the session | C33: 20 Oct | D33: 22 Oct | E33: =IF(OR(CL33="",CM33=""),"",CM33-CL33+1) -> 3 | F33: Done | CJ33: Task | CL33: =IFERROR(IF(TRIM(C33)="","",IF(ISNUMBER(C33),C33,DATE(2026,MATCH(LEFT(MID(TRIM(C33),FIND(" ",TRIM(C33))+1,9),3),Lists!$A$1:$A$12,0),VALUE(LEFT(TRIM(C33),FIND(" ",TRIM(C33))-1))))),"") -> 46315 | CM33: =IFERROR(IF(TRIM(D33)="","",IF(ISNUMBER(D33),D33,DATE(2026,MATCH(LEFT(MID(TRIM(D33),FIND(" ",TRIM(D33))+1,9),3),Lists!$A$1:$A$12,0),VALUE(LEFT(TRIM(D33),FIND(" ",TRIM(D33))-1))))),"") -> 46317
A34: Wrist-height tempo and lowering-speed check | C34: 26 Oct | D34: 27 Oct | E34: =IF(OR(CL34="",CM34=""),"",CM34-CL34+1) -> 2 | F34: Done | CJ34: Task | CL34: =IFERROR(IF(TRIM(C34)="","",IF(ISNUMBER(C34),C34,DATE(2026,MATCH(LEFT(MID(TRIM(C34),FIND(" ",TRIM(C34))+1,9),3),Lists!$A$1:$A$12,0),VALUE(LEFT(TRIM(C34),FIND(" ",TRIM(C34))-1))))),"") -> 46321 | CM34: =IFERROR(IF(TRIM(D34)="","",IF(ISNUMBER(D34),D34,DATE(2026,MATCH(LEFT(MID(TRIM(D34),FIND(" ",TRIM(D34))+1,9),3),Lists!$A$1:$A$12,0),VALUE(LEFT(TRIM(D34),FIND(" ",TRIM(D34))-1))))),"") -> 46322
A35: 7. Test OpenCV/MediaPipe detection under varying lighting conditions | B35: W7 | C35: =DAY(CL35)&" "&INDEX(Lists!$A$1:$A$12,MONTH(CL35)) -> 20 Oct | D35: =DAY(CM35)&" "&INDEX(Lists!$A$1:$A$12,MONTH(CM35)) -> 11 Nov | E35: =CM35-CL35+1 -> 23 | F35: =IF(COUNTIF(F36:F37,"Done")=2,"Done",IF(COUNTIF(F36:F37,"Not started")=2,"Not started","In progress")) -> In progress | CJ35: Heading | CL35: =MIN(CL36:CL37) -> 46315 | CM35: =MAX(CM36:CM37) -> 46337
A36: Record test clips for repeatable testing (tools/record_clips.py) | C36: 20 Oct | D36: 27 Oct | E36: =IF(OR(CL36="",CM36=""),"",CM36-CL36+1) -> 8 | F36: Done | CJ36: Task | CL36: =IFERROR(IF(TRIM(C36)="","",IF(ISNUMBER(C36),C36,DATE(2026,MATCH(LEFT(MID(TRIM(C36),FIND(" ",TRIM(C36))+1,9),3),Lists!$A$1:$A$12,0),VALUE(LEFT(TRIM(C36),FIND(" ",TRIM(C36))-1))))),"") -> 46315 | CM36: =IFERROR(IF(TRIM(D36)="","",IF(ISNUMBER(D36),D36,DATE(2026,MATCH(LEFT(MID(TRIM(D36),FIND(" ",TRIM(D36))+1,9),3),Lists!$A$1:$A$12,0),VALUE(LEFT(TRIM(D36),FIND(" ",TRIM(D36))-1))))),"") -> 46322
A37: Lighting tests (bright, dim, backlit) and record results | C37: 9 Nov | D37: 11 Nov | E37: =IF(OR(CL37="",CM37=""),"",CM37-CL37+1) -> 3 | F37: Not started | CJ37: Task | CL37: =IFERROR(IF(TRIM(C37)="","",IF(ISNUMBER(C37),C37,DATE(2026,MATCH(LEFT(MID(TRIM(C37),FIND(" ",TRIM(C37))+1,9),3),Lists!$A$1:$A$12,0),VALUE(LEFT(TRIM(C37),FIND(" ",TRIM(C37))-1))))),"") -> 46335 | CM37: =IFERROR(IF(TRIM(D37)="","",IF(ISNUMBER(D37),D37,DATE(2026,MATCH(LEFT(MID(TRIM(D37),FIND(" ",TRIM(D37))+1,9),3),Lists!$A$1:$A$12,0),VALUE(LEFT(TRIM(D37),FIND(" ",TRIM(D37))-1))))),"") -> 46337
A38: 8. Test detection under varying distances/backgrounds; tune thresholds for stability | B38: W8 | C38: =DAY(CL38)&" "&INDEX(Lists!$A$1:$A$12,MONTH(CL38)) -> 8 Oct | D38: =DAY(CM38)&" "&INDEX(Lists!$A$1:$A$12,MONTH(CM38)) -> 12 Nov | E38: =CM38-CL38+1 -> 36 | F38: =IF(COUNTIF(F39:F41,"Done")=3,"Done",IF(COUNTIF(F39:F41,"Not started")=3,"Not started","In progress")) -> In progress | CJ38: Heading | CL38: =MIN(CL39:CL41) -> 46303 | CM38: =MAX(CM39:CM41) -> 46338
A39: Tune angle, visibility and confidence thresholds | C39: 8 Oct | D39: 27 Oct | E39: =IF(OR(CL39="",CM39=""),"",CM39-CL39+1) -> 20 | F39: Done | CJ39: Task | CL39: =IFERROR(IF(TRIM(C39)="","",IF(ISNUMBER(C39),C39,DATE(2026,MATCH(LEFT(MID(TRIM(C39),FIND(" ",TRIM(C39))+1,9),3),Lists!$A$1:$A$12,0),VALUE(LEFT(TRIM(C39),FIND(" ",TRIM(C39))-1))))),"") -> 46303 | CM39: =IFERROR(IF(TRIM(D39)="","",IF(ISNUMBER(D39),D39,DATE(2026,MATCH(LEFT(MID(TRIM(D39),FIND(" ",TRIM(D39))+1,9),3),Lists!$A$1:$A$12,0),VALUE(LEFT(TRIM(D39),FIND(" ",TRIM(D39))-1))))),"") -> 46322
A40: Distance and background tests and record results | C40: 10 Nov | D40: 12 Nov | E40: =IF(OR(CL40="",CM40=""),"",CM40-CL40+1) -> 3 | F40: Not started | CJ40: Task | CL40: =IFERROR(IF(TRIM(C40)="","",IF(ISNUMBER(C40),C40,DATE(2026,MATCH(LEFT(MID(TRIM(C40),FIND(" ",TRIM(C40))+1,9),3),Lists!$A$1:$A$12,0),VALUE(LEFT(TRIM(C40),FIND(" ",TRIM(C40))-1))))),"") -> 46336 | CM40: =IFERROR(IF(TRIM(D40)="","",IF(ISNUMBER(D40),D40,DATE(2026,MATCH(LEFT(MID(TRIM(D40),FIND(" ",TRIM(D40))+1,9),3),Lists!$A$1:$A$12,0),VALUE(LEFT(TRIM(D40),FIND(" ",TRIM(D40))-1))))),"") -> 46338
A41: Frame-rate check on the Pi 5 (CNN every 3rd frame, camera watchdog) | C41: 27 Oct | D41: 6 Nov | E41: =IF(OR(CL41="",CM41=""),"",CM41-CL41+1) -> 11 | F41: In progress | CJ41: Task | CL41: =IFERROR(IF(TRIM(C41)="","",IF(ISNUMBER(C41),C41,DATE(2026,MATCH(LEFT(MID(TRIM(C41),FIND(" ",TRIM(C41))+1,9),3),Lists!$A$1:$A$12,0),VALUE(LEFT(TRIM(C41),FIND(" ",TRIM(C41))-1))))),"") -> 46322 | CM41: =IFERROR(IF(TRIM(D41)="","",IF(ISNUMBER(D41),D41,DATE(2026,MATCH(LEFT(MID(TRIM(D41),FIND(" ",TRIM(D41))+1,9),3),Lists!$A$1:$A$12,0),VALUE(LEFT(TRIM(D41),FIND(" ",TRIM(D41))-1))))),"") -> 46332
A42: 9. Develop supporting modules: display overlay, GPIO feedback, calorie tracking, session logging (CSV) | B42: W9 | C42: =DAY(CL42)&" "&INDEX(Lists!$A$1:$A$12,MONTH(CL42)) -> 21 Sep | D42: =DAY(CM42)&" "&INDEX(Lists!$A$1:$A$12,MONTH(CM42)) -> 6 Nov | E42: =CM42-CL42+1 -> 47 | F42: =IF(COUNTIF(F43:F47,"Done")=5,"Done",IF(COUNTIF(F43:F47,"Not started")=5,"Not started","In progress")) -> In progress | CJ42: Heading | CL42: =MIN(CL43:CL47) -> 46286 | CM42: =MAX(CM43:CM47) -> 46332
...

Sheet Lists
A1: Jan
A2: Feb
A3: Mar
A4: Apr
A5: May
A6: Jun
A7: Jul
A8: Aug
A9: Sep
A10: Oct
A11: Nov
A12: Dec

Sheet Outline vs Actual
A1: Comparison with the Project Outline Gantt chart (Appendix A)
A2: Term week 1 = 14-20 Sep 2026, so outline week Wn = the n-th week from 14 Sep.
A4: Outline task | B4: Outline week (dates) | C4: Updated span | D4: Status (31 Oct) | E4: Change and reason
A5: Set up Python 3.11 virtual environment (Raspberry Pi OS + laptop) | B5: W1 (14 Sep - 20 Sep) | C5: 14 Sep - 02 Oct | D5: Done | E5: Took longer: Raspberry Pi OS Trixie ships Python 3.13, which MediaPipe does not support, so a Python 3.12 environment was made with uv.
A6: Install and configure OpenCV | B6: W2 (21 Sep - 27 Sep) | C6: 16 Sep - 02 Oct | D6: Done | E6: Laptop done in W1; the Pi part was done together with task 1 in W3.
A7: Install and configure MediaPipe; test camera feed and GPIO wiring for LED/buzzer | B7: W3 (28 Sep - 04 Oct) | C7: 17 Sep - 04 Nov | D7: In progress | E7: MediaPipe and camera done (AI Camera needed its firmware). GPIO wiring moved to early November to keep the focus on the software (critical path).
A8: Develop MediaPipe Pose landmark extraction (shoulder, elbow, wrist, hip coordinates) | B8: W4 (05 Oct - 11 Oct) | C8: 19 Sep - 07 Oct | D8: Done | E8: Done early on the laptop (W1-W2); 3D landmarks added in W4.
A9: Implement joint-angle calculation functions (elbow, torso, wrist angles) | B9: W5 (12 Oct - 18 Oct) | C9: 05 Oct - 08 Oct | D9: Done | E9: Done in W4; wrist angle from the hand knuckles; hip angle replaced by an upper-arm drift check because the hips are often out of view.
A10: Build the bicep curl rep-counting state machine with form-validation checks | B10: W6 (19 Oct - 25 Oct) | C10: 21 Sep - 27 Oct | D10: Done | E10: Started early on the laptop (W2); live counting on the Pi took until 22 Oct. Fist direction could not be judged reliably from one camera; agreed with the supervisor to leave it as a limitation (advice only).
A11: Test OpenCV/MediaPipe detection under varying lighting conditions | B11: W7 (26 Oct - 01 Nov) | C11: 20 Oct - 11 Nov | D11: In progress | E11: Test clips recorded in W6 so every change is tested on the same video; the formal lighting tests are run in W9 with the finished system.
A12: Test detection under varying distances/backgrounds; tune thresholds for stability | B12: W8 (02 Nov - 08 Nov) | C12: 08 Oct - 12 Nov | D12: In progress | E12: Threshold tuning started early (W4) because counting did not work on the Pi; distance/background tests in W9.
A13: Develop supporting modules: display overlay, GPIO feedback, calorie tracking, session logging (CSV) | B13: W9 (09 Nov - 15 Nov) | C13: 21 Sep - 06 Nov | D13: In progress | E13: Grew in scope: the CSV log became a Flask phone app with accounts, QR login, session history, calorie chart and a goal for the next session (W5-W7). GPIO feedback moved to W8.
A14: Design and 3D print the Raspberry Pi/display/LED enclosure (Bambu Lab X1 Carbon, PLA) | B14: W10 (16 Nov - 22 Nov) | C14: 02 Oct - 13 Nov | D14: In progress | E14: CAD started early but paused while the software was fixed; the supervisor asked for a polished chassis, so the redesign and printing are W8-W9.
A15: Assemble hardware into the enclosure; integrate pipeline on Raspberry Pi 5 (camera, GPIO, Flask endpoint) | B15: W11 (23 Nov - 29 Nov) | C15: 21 Oct - 15 Nov | D15: In progress | E15: Software integration on the Pi finished in W6-W7 (both cameras, phone app); mounting in the enclosure in W9.
... A20: VIVA slides and rehearsal (added) | B20: - | C20: 26 Nov - 01 Dec | D20: Not started | E20: Not in the outline; slides due 30 Nov, VIVA 2 Dec.
